[2024-12-14T10:37:26.493+0000] {taskinstance.py:1159} INFO - Dependencies all met for dep_context=non-requeueable deps ti=<TaskInstance: kafka_spark_dag.kafka_data_stream scheduled__2024-12-13T10:37:08.470867+00:00 [queued]>
[2024-12-14T10:37:26.511+0000] {taskinstance.py:1159} INFO - Dependencies all met for dep_context=requeueable deps ti=<TaskInstance: kafka_spark_dag.kafka_data_stream scheduled__2024-12-13T10:37:08.470867+00:00 [queued]>
[2024-12-14T10:37:26.512+0000] {taskinstance.py:1361} INFO - Starting attempt 1 of 2
[2024-12-14T10:37:26.535+0000] {taskinstance.py:1382} INFO - Executing <Task(PythonOperator): kafka_data_stream> on 2024-12-13 10:37:08.470867+00:00
[2024-12-14T10:37:26.546+0000] {standard_task_runner.py:57} INFO - Started process 929 to run task
[2024-12-14T10:37:26.553+0000] {standard_task_runner.py:84} INFO - Running: ['***', 'tasks', 'run', 'kafka_spark_dag', 'kafka_data_stream', 'scheduled__2024-12-13T10:37:08.470867+00:00', '--job-id', '2', '--raw', '--subdir', 'DAGS_FOLDER/dag_kafka_spark.py', '--cfg-path', '/tmp/tmpeyv68y9m']
[2024-12-14T10:37:26.559+0000] {standard_task_runner.py:85} INFO - Job 2: Subtask kafka_data_stream
[2024-12-14T10:37:26.648+0000] {task_command.py:416} INFO - Running <TaskInstance: kafka_spark_dag.kafka_data_stream scheduled__2024-12-13T10:37:08.470867+00:00 [running]> on host 90542c89da23
[2024-12-14T10:37:26.764+0000] {taskinstance.py:1662} INFO - Exporting env vars: AIRFLOW_CTX_DAG_OWNER='***' AIRFLOW_CTX_DAG_ID='kafka_spark_dag' AIRFLOW_CTX_TASK_ID='kafka_data_stream' AIRFLOW_CTX_EXECUTION_DATE='2024-12-13T10:37:08.470867+00:00' AIRFLOW_CTX_TRY_NUMBER='1' AIRFLOW_CTX_DAG_RUN_ID='scheduled__2024-12-13T10:37:08.470867+00:00'
[2024-12-14T10:37:26.970+0000] {conn.py:380} INFO - <BrokerConnection node_id=bootstrap-0 host=kafka:9092 <connecting> [IPv4 ('172.18.0.2', 9092)]>: connecting to kafka:9092 [('172.18.0.2', 9092) IPv4]
[2024-12-14T10:37:26.972+0000] {conn.py:1205} INFO - Probing node bootstrap-0 broker version
[2024-12-14T10:37:26.975+0000] {conn.py:410} INFO - <BrokerConnection node_id=bootstrap-0 host=kafka:9092 <connecting> [IPv4 ('172.18.0.2', 9092)]>: Connection complete.
[2024-12-14T10:37:27.087+0000] {conn.py:1267} INFO - Broker version identified as 2.5.0
[2024-12-14T10:37:27.089+0000] {conn.py:1268} INFO - Set configuration api_version=(2, 5, 0) to skip auto check_version requests on startup
[2024-12-14T10:37:36.060+0000] {kafka_stream_data.py:131} ERROR - Error in main loop: 'Submission' object has no attribute 'is_original'
[2024-12-14T10:38:37.924+0000] {kafka_stream_data.py:131} ERROR - Error in main loop: 'Submission' object has no attribute 'is_original'
[2024-12-14T10:39:40.065+0000] {kafka_stream_data.py:131} ERROR - Error in main loop: 'Submission' object has no attribute 'is_original'
[2024-12-14T10:40:42.112+0000] {kafka_stream_data.py:131} ERROR - Error in main loop: 'Submission' object has no attribute 'is_original'
[2024-12-14T10:41:44.273+0000] {kafka_stream_data.py:131} ERROR - Error in main loop: 'Submission' object has no attribute 'is_original'
[2024-12-14T10:42:27.157+0000] {conn.py:380} INFO - <BrokerConnection node_id=0 host=kafka:9092 <connecting> [IPv4 ('172.18.0.2', 9092)]>: connecting to kafka:9092 [('172.18.0.2', 9092) IPv4]
[2024-12-14T10:42:27.161+0000] {conn.py:410} INFO - <BrokerConnection node_id=0 host=kafka:9092 <connecting> [IPv4 ('172.18.0.2', 9092)]>: Connection complete.
[2024-12-14T10:42:27.164+0000] {conn.py:919} INFO - <BrokerConnection node_id=bootstrap-0 host=kafka:9092 <connected> [IPv4 ('172.18.0.2', 9092)]>: Closing connection. 
[2024-12-14T10:42:45.918+0000] {kafka_stream_data.py:131} ERROR - Error in main loop: 'Submission' object has no attribute 'is_original'
[2024-12-14T10:43:48.892+0000] {kafka_stream_data.py:131} ERROR - Error in main loop: 'Submission' object has no attribute 'is_original'
[2024-12-14T10:44:51.371+0000] {kafka_stream_data.py:131} ERROR - Error in main loop: 'Submission' object has no attribute 'is_original'
[2024-12-14T10:45:55.973+0000] {kafka_stream_data.py:131} ERROR - Error in main loop: 'Submission' object has no attribute 'is_original'
[2024-12-14T10:46:58.537+0000] {kafka_stream_data.py:131} ERROR - Error in main loop: 'Submission' object has no attribute 'is_original'
[2024-12-14T10:48:01.583+0000] {kafka_stream_data.py:131} ERROR - Error in main loop: 'Submission' object has no attribute 'is_original'
[2024-12-14T10:49:04.392+0000] {kafka_stream_data.py:131} ERROR - Error in main loop: 'Submission' object has no attribute 'is_original'
[2024-12-14T10:50:05.931+0000] {kafka_stream_data.py:131} ERROR - Error in main loop: 'Submission' object has no attribute 'is_original'
[2024-12-14T10:51:07.469+0000] {kafka_stream_data.py:131} ERROR - Error in main loop: 'Submission' object has no attribute 'is_original'
[2024-12-14T10:51:41.672+0000] {local_task_job_runner.py:115} ERROR - Received SIGTERM. Terminating subprocesses
[2024-12-14T10:51:41.701+0000] {process_utils.py:131} INFO - Sending 15 to group 929. PIDs of all processes in the group: [929]
[2024-12-14T10:51:41.710+0000] {process_utils.py:86} INFO - Sending the signal 15 to group 929
[2024-12-14T10:51:41.717+0000] {taskinstance.py:1632} ERROR - Received SIGTERM. Terminating subprocesses.
[2024-12-14T10:51:41.918+0000] {conn.py:919} INFO - <BrokerConnection node_id=0 host=kafka:9092 <connected> [IPv4 ('172.18.0.2', 9092)]>: Closing connection. KafkaConnectionError: Socket EVENT_READ without in-flight-requests
[2024-12-14T10:51:41.921+0000] {client_async.py:331} WARNING - Node 0 connection failed -- refreshing metadata
[2024-12-14T10:51:41.979+0000] {conn.py:380} INFO - <BrokerConnection node_id=0 host=kafka:9092 <connecting> [IPv4 ('172.18.0.2', 9092)]>: connecting to kafka:9092 [('172.18.0.2', 9092) IPv4]
[2024-12-14T10:51:41.982+0000] {conn.py:418} ERROR - Connect attempt to <BrokerConnection node_id=0 host=kafka:9092 <connecting> [IPv4 ('172.18.0.2', 9092)]> returned error 111. Disconnecting.
[2024-12-14T10:51:41.985+0000] {conn.py:919} INFO - <BrokerConnection node_id=0 host=kafka:9092 <connecting> [IPv4 ('172.18.0.2', 9092)]>: Closing connection. KafkaConnectionError: 111 ECONNREFUSED
[2024-12-14T10:51:41.988+0000] {client_async.py:331} WARNING - Node 0 connection failed -- refreshing metadata
[2024-12-14T10:51:42.147+0000] {conn.py:380} INFO - <BrokerConnection node_id=0 host=kafka:9092 <connecting> [IPv4 ('172.18.0.2', 9092)]>: connecting to kafka:9092 [('172.18.0.2', 9092) IPv4]
[2024-12-14T10:51:42.152+0000] {conn.py:418} ERROR - Connect attempt to <BrokerConnection node_id=0 host=kafka:9092 <connecting> [IPv4 ('172.18.0.2', 9092)]> returned error 111. Disconnecting.
[2024-12-14T10:51:42.155+0000] {conn.py:919} INFO - <BrokerConnection node_id=0 host=kafka:9092 <connecting> [IPv4 ('172.18.0.2', 9092)]>: Closing connection. KafkaConnectionError: 111 ECONNREFUSED
[2024-12-14T10:51:42.157+0000] {client_async.py:331} WARNING - Node 0 connection failed -- refreshing metadata
[2024-12-14T10:51:42.419+0000] {conn.py:380} INFO - <BrokerConnection node_id=0 host=kafka:9092 <connecting> [IPv4 ('172.18.0.2', 9092)]>: connecting to kafka:9092 [('172.18.0.2', 9092) IPv4]
[2024-12-14T10:51:42.423+0000] {conn.py:418} ERROR - Connect attempt to <BrokerConnection node_id=0 host=kafka:9092 <connecting> [IPv4 ('172.18.0.2', 9092)]> returned error 111. Disconnecting.
[2024-12-14T10:51:42.429+0000] {conn.py:919} INFO - <BrokerConnection node_id=0 host=kafka:9092 <connecting> [IPv4 ('172.18.0.2', 9092)]>: Closing connection. KafkaConnectionError: 111 ECONNREFUSED
[2024-12-14T10:51:42.430+0000] {client_async.py:331} WARNING - Node 0 connection failed -- refreshing metadata
[2024-12-14T10:51:42.844+0000] {conn.py:380} INFO - <BrokerConnection node_id=0 host=kafka:9092 <connecting> [IPv4 ('172.18.0.2', 9092)]>: connecting to kafka:9092 [('172.18.0.2', 9092) IPv4]
[2024-12-14T10:51:42.847+0000] {conn.py:418} ERROR - Connect attempt to <BrokerConnection node_id=0 host=kafka:9092 <connecting> [IPv4 ('172.18.0.2', 9092)]> returned error 111. Disconnecting.
[2024-12-14T10:51:42.849+0000] {conn.py:919} INFO - <BrokerConnection node_id=0 host=kafka:9092 <connecting> [IPv4 ('172.18.0.2', 9092)]>: Closing connection. KafkaConnectionError: 111 ECONNREFUSED
[2024-12-14T10:51:42.851+0000] {client_async.py:331} WARNING - Node 0 connection failed -- refreshing metadata
[2024-12-14T10:51:42.894+0000] {standard_task_runner.py:104} ERROR - Failed to execute job 2 for task kafka_data_stream ((psycopg2.OperationalError) could not translate host name "postgres" to address: Name or service not known

(Background on this error at: https://sqlalche.me/e/14/e3q8); 929)
[2024-12-14T10:51:42.957+0000] {process_utils.py:79} INFO - Process psutil.Process(pid=929, status='terminated', exitcode=1, started='10:37:26') (929) terminated with exit code 1
[2024-12-14T10:51:42.960+0000] {local_task_job_runner.py:228} INFO - Task exited with return code 143
[2024-12-14T10:51:42.987+0000] {taskinstance.py:2784} INFO - Skipping mini scheduling run due to exception: None
Traceback (most recent call last):
  File "/home/airflow/.local/lib/python3.8/site-packages/sqlalchemy/engine/base.py", line 3371, in _wrap_pool_connect
    return fn()
  File "/home/airflow/.local/lib/python3.8/site-packages/sqlalchemy/pool/base.py", line 327, in connect
    return _ConnectionFairy._checkout(self)
  File "/home/airflow/.local/lib/python3.8/site-packages/sqlalchemy/pool/base.py", line 894, in _checkout
    fairy = _ConnectionRecord.checkout(pool)
  File "/home/airflow/.local/lib/python3.8/site-packages/sqlalchemy/pool/base.py", line 493, in checkout
    rec = pool._do_get()
  File "/home/airflow/.local/lib/python3.8/site-packages/sqlalchemy/pool/impl.py", line 256, in _do_get
    return self._create_connection()
  File "/home/airflow/.local/lib/python3.8/site-packages/sqlalchemy/pool/base.py", line 273, in _create_connection
    return _ConnectionRecord(self)
  File "/home/airflow/.local/lib/python3.8/site-packages/sqlalchemy/pool/base.py", line 388, in __init__
    self.__connect()
  File "/home/airflow/.local/lib/python3.8/site-packages/sqlalchemy/pool/base.py", line 691, in __connect
    pool.logger.debug("Error on connect(): %s", e)
  File "/home/airflow/.local/lib/python3.8/site-packages/sqlalchemy/util/langhelpers.py", line 70, in __exit__
    compat.raise_(
  File "/home/airflow/.local/lib/python3.8/site-packages/sqlalchemy/util/compat.py", line 211, in raise_
    raise exception
  File "/home/airflow/.local/lib/python3.8/site-packages/sqlalchemy/pool/base.py", line 686, in __connect
    self.dbapi_connection = connection = pool._invoke_creator(self)
  File "/home/airflow/.local/lib/python3.8/site-packages/sqlalchemy/engine/create.py", line 574, in connect
    return dialect.connect(*cargs, **cparams)
  File "/home/airflow/.local/lib/python3.8/site-packages/sqlalchemy/engine/default.py", line 598, in connect
    return self.dbapi.connect(*cargs, **cparams)
  File "/home/airflow/.local/lib/python3.8/site-packages/psycopg2/__init__.py", line 122, in connect
    conn = _connect(dsn, connection_factory=connection_factory, **kwasync)
psycopg2.OperationalError: could not translate host name "postgres" to address: Name or service not known


The above exception was the direct cause of the following exception:

Traceback (most recent call last):
  File "/home/airflow/.local/lib/python3.8/site-packages/airflow/models/taskinstance.py", line 2733, in schedule_downstream_tasks
    dag_run = with_row_locks(
  File "/home/airflow/.local/lib/python3.8/site-packages/sqlalchemy/orm/query.py", line 2870, in one
    return self._iter().one()
  File "/home/airflow/.local/lib/python3.8/site-packages/sqlalchemy/orm/query.py", line 2916, in _iter
    result = self.session.execute(
  File "/home/airflow/.local/lib/python3.8/site-packages/sqlalchemy/orm/session.py", line 1716, in execute
    conn = self._connection_for_bind(bind)
  File "/home/airflow/.local/lib/python3.8/site-packages/sqlalchemy/orm/session.py", line 1555, in _connection_for_bind
    return self._transaction._connection_for_bind(
  File "/home/airflow/.local/lib/python3.8/site-packages/sqlalchemy/orm/session.py", line 750, in _connection_for_bind
    conn = bind.connect()
  File "/home/airflow/.local/lib/python3.8/site-packages/sqlalchemy/future/engine.py", line 406, in connect
    return super(Engine, self).connect()
  File "/home/airflow/.local/lib/python3.8/site-packages/sqlalchemy/engine/base.py", line 3325, in connect
    return self._connection_cls(self, close_with_result=close_with_result)
  File "/home/airflow/.local/lib/python3.8/site-packages/sqlalchemy/engine/base.py", line 96, in __init__
    else engine.raw_connection()
  File "/home/airflow/.local/lib/python3.8/site-packages/sqlalchemy/engine/base.py", line 3404, in raw_connection
    return self._wrap_pool_connect(self.pool.connect, _connection)
  File "/home/airflow/.local/lib/python3.8/site-packages/sqlalchemy/engine/base.py", line 3374, in _wrap_pool_connect
    Connection._handle_dbapi_exception_noconnection(
  File "/home/airflow/.local/lib/python3.8/site-packages/sqlalchemy/engine/base.py", line 2208, in _handle_dbapi_exception_noconnection
    util.raise_(
  File "/home/airflow/.local/lib/python3.8/site-packages/sqlalchemy/util/compat.py", line 211, in raise_
    raise exception
  File "/home/airflow/.local/lib/python3.8/site-packages/sqlalchemy/engine/base.py", line 3371, in _wrap_pool_connect
    return fn()
  File "/home/airflow/.local/lib/python3.8/site-packages/sqlalchemy/pool/base.py", line 327, in connect
    return _ConnectionFairy._checkout(self)
  File "/home/airflow/.local/lib/python3.8/site-packages/sqlalchemy/pool/base.py", line 894, in _checkout
    fairy = _ConnectionRecord.checkout(pool)
  File "/home/airflow/.local/lib/python3.8/site-packages/sqlalchemy/pool/base.py", line 493, in checkout
    rec = pool._do_get()
  File "/home/airflow/.local/lib/python3.8/site-packages/sqlalchemy/pool/impl.py", line 256, in _do_get
    return self._create_connection()
  File "/home/airflow/.local/lib/python3.8/site-packages/sqlalchemy/pool/base.py", line 273, in _create_connection
    return _ConnectionRecord(self)
  File "/home/airflow/.local/lib/python3.8/site-packages/sqlalchemy/pool/base.py", line 388, in __init__
    self.__connect()
  File "/home/airflow/.local/lib/python3.8/site-packages/sqlalchemy/pool/base.py", line 691, in __connect
    pool.logger.debug("Error on connect(): %s", e)
  File "/home/airflow/.local/lib/python3.8/site-packages/sqlalchemy/util/langhelpers.py", line 70, in __exit__
    compat.raise_(
  File "/home/airflow/.local/lib/python3.8/site-packages/sqlalchemy/util/compat.py", line 211, in raise_
    raise exception
  File "/home/airflow/.local/lib/python3.8/site-packages/sqlalchemy/pool/base.py", line 686, in __connect
    self.dbapi_connection = connection = pool._invoke_creator(self)
  File "/home/airflow/.local/lib/python3.8/site-packages/sqlalchemy/engine/create.py", line 574, in connect
    return dialect.connect(*cargs, **cparams)
  File "/home/airflow/.local/lib/python3.8/site-packages/sqlalchemy/engine/default.py", line 598, in connect
    return self.dbapi.connect(*cargs, **cparams)
  File "/home/airflow/.local/lib/python3.8/site-packages/psycopg2/__init__.py", line 122, in connect
    conn = _connect(dsn, connection_factory=connection_factory, **kwasync)
sqlalchemy.exc.OperationalError: (psycopg2.OperationalError) could not translate host name "postgres" to address: Name or service not known

(Background on this error at: https://sqlalche.me/e/14/e3q8)
[2024-12-14T10:51:43.030+0000] {job.py:219} ERROR - Job heartbeat got an exception
Traceback (most recent call last):
  File "/home/airflow/.local/lib/python3.8/site-packages/sqlalchemy/engine/base.py", line 3371, in _wrap_pool_connect
    return fn()
  File "/home/airflow/.local/lib/python3.8/site-packages/sqlalchemy/pool/base.py", line 327, in connect
    return _ConnectionFairy._checkout(self)
  File "/home/airflow/.local/lib/python3.8/site-packages/sqlalchemy/pool/base.py", line 894, in _checkout
    fairy = _ConnectionRecord.checkout(pool)
  File "/home/airflow/.local/lib/python3.8/site-packages/sqlalchemy/pool/base.py", line 493, in checkout
    rec = pool._do_get()
  File "/home/airflow/.local/lib/python3.8/site-packages/sqlalchemy/pool/impl.py", line 256, in _do_get
    return self._create_connection()
  File "/home/airflow/.local/lib/python3.8/site-packages/sqlalchemy/pool/base.py", line 273, in _create_connection
    return _ConnectionRecord(self)
  File "/home/airflow/.local/lib/python3.8/site-packages/sqlalchemy/pool/base.py", line 388, in __init__
    self.__connect()
  File "/home/airflow/.local/lib/python3.8/site-packages/sqlalchemy/pool/base.py", line 691, in __connect
    pool.logger.debug("Error on connect(): %s", e)
  File "/home/airflow/.local/lib/python3.8/site-packages/sqlalchemy/util/langhelpers.py", line 70, in __exit__
    compat.raise_(
  File "/home/airflow/.local/lib/python3.8/site-packages/sqlalchemy/util/compat.py", line 211, in raise_
    raise exception
  File "/home/airflow/.local/lib/python3.8/site-packages/sqlalchemy/pool/base.py", line 686, in __connect
    self.dbapi_connection = connection = pool._invoke_creator(self)
  File "/home/airflow/.local/lib/python3.8/site-packages/sqlalchemy/engine/create.py", line 574, in connect
    return dialect.connect(*cargs, **cparams)
  File "/home/airflow/.local/lib/python3.8/site-packages/sqlalchemy/engine/default.py", line 598, in connect
    return self.dbapi.connect(*cargs, **cparams)
  File "/home/airflow/.local/lib/python3.8/site-packages/psycopg2/__init__.py", line 122, in connect
    conn = _connect(dsn, connection_factory=connection_factory, **kwasync)
psycopg2.OperationalError: could not translate host name "postgres" to address: Name or service not known


The above exception was the direct cause of the following exception:

Traceback (most recent call last):
  File "/home/airflow/.local/lib/python3.8/site-packages/airflow/jobs/job.py", line 190, in heartbeat
    session.merge(self)
  File "/home/airflow/.local/lib/python3.8/site-packages/sqlalchemy/orm/session.py", line 3056, in merge
    return self._merge(
  File "/home/airflow/.local/lib/python3.8/site-packages/sqlalchemy/orm/session.py", line 3136, in _merge
    merged = self.get(
  File "/home/airflow/.local/lib/python3.8/site-packages/sqlalchemy/orm/session.py", line 2853, in get
    return self._get_impl(
  File "/home/airflow/.local/lib/python3.8/site-packages/sqlalchemy/orm/session.py", line 2975, in _get_impl
    return db_load_fn(
  File "/home/airflow/.local/lib/python3.8/site-packages/sqlalchemy/orm/loading.py", line 530, in load_on_pk_identity
    session.execute(
  File "/home/airflow/.local/lib/python3.8/site-packages/sqlalchemy/orm/session.py", line 1716, in execute
    conn = self._connection_for_bind(bind)
  File "/home/airflow/.local/lib/python3.8/site-packages/sqlalchemy/orm/session.py", line 1555, in _connection_for_bind
    return self._transaction._connection_for_bind(
  File "/home/airflow/.local/lib/python3.8/site-packages/sqlalchemy/orm/session.py", line 750, in _connection_for_bind
    conn = bind.connect()
  File "/home/airflow/.local/lib/python3.8/site-packages/sqlalchemy/future/engine.py", line 406, in connect
    return super(Engine, self).connect()
  File "/home/airflow/.local/lib/python3.8/site-packages/sqlalchemy/engine/base.py", line 3325, in connect
    return self._connection_cls(self, close_with_result=close_with_result)
  File "/home/airflow/.local/lib/python3.8/site-packages/sqlalchemy/engine/base.py", line 96, in __init__
    else engine.raw_connection()
  File "/home/airflow/.local/lib/python3.8/site-packages/sqlalchemy/engine/base.py", line 3404, in raw_connection
    return self._wrap_pool_connect(self.pool.connect, _connection)
  File "/home/airflow/.local/lib/python3.8/site-packages/sqlalchemy/engine/base.py", line 3374, in _wrap_pool_connect
    Connection._handle_dbapi_exception_noconnection(
  File "/home/airflow/.local/lib/python3.8/site-packages/sqlalchemy/engine/base.py", line 2208, in _handle_dbapi_exception_noconnection
    util.raise_(
  File "/home/airflow/.local/lib/python3.8/site-packages/sqlalchemy/util/compat.py", line 211, in raise_
    raise exception
  File "/home/airflow/.local/lib/python3.8/site-packages/sqlalchemy/engine/base.py", line 3371, in _wrap_pool_connect
    return fn()
  File "/home/airflow/.local/lib/python3.8/site-packages/sqlalchemy/pool/base.py", line 327, in connect
    return _ConnectionFairy._checkout(self)
  File "/home/airflow/.local/lib/python3.8/site-packages/sqlalchemy/pool/base.py", line 894, in _checkout
    fairy = _ConnectionRecord.checkout(pool)
  File "/home/airflow/.local/lib/python3.8/site-packages/sqlalchemy/pool/base.py", line 493, in checkout
    rec = pool._do_get()
  File "/home/airflow/.local/lib/python3.8/site-packages/sqlalchemy/pool/impl.py", line 256, in _do_get
    return self._create_connection()
  File "/home/airflow/.local/lib/python3.8/site-packages/sqlalchemy/pool/base.py", line 273, in _create_connection
    return _ConnectionRecord(self)
  File "/home/airflow/.local/lib/python3.8/site-packages/sqlalchemy/pool/base.py", line 388, in __init__
    self.__connect()
  File "/home/airflow/.local/lib/python3.8/site-packages/sqlalchemy/pool/base.py", line 691, in __connect
    pool.logger.debug("Error on connect(): %s", e)
  File "/home/airflow/.local/lib/python3.8/site-packages/sqlalchemy/util/langhelpers.py", line 70, in __exit__
    compat.raise_(
  File "/home/airflow/.local/lib/python3.8/site-packages/sqlalchemy/util/compat.py", line 211, in raise_
    raise exception
  File "/home/airflow/.local/lib/python3.8/site-packages/sqlalchemy/pool/base.py", line 686, in __connect
    self.dbapi_connection = connection = pool._invoke_creator(self)
  File "/home/airflow/.local/lib/python3.8/site-packages/sqlalchemy/engine/create.py", line 574, in connect
    return dialect.connect(*cargs, **cparams)
  File "/home/airflow/.local/lib/python3.8/site-packages/sqlalchemy/engine/default.py", line 598, in connect
    return self.dbapi.connect(*cargs, **cparams)
  File "/home/airflow/.local/lib/python3.8/site-packages/psycopg2/__init__.py", line 122, in connect
    conn = _connect(dsn, connection_factory=connection_factory, **kwasync)
sqlalchemy.exc.OperationalError: (psycopg2.OperationalError) could not translate host name "postgres" to address: Name or service not known

(Background on this error at: https://sqlalche.me/e/14/e3q8)
